<!-- Simplified model file for debugging -->
<mujoco model="yobotics_simple">
    <compiler 
        angle="degree" 
        inertiafromgeom="true" 
        coordinate="local"
        meshdir="../meshes/"
    />
    
    <option 
        timestep="0.001"
        iterations="50" 
        solver="Newton" 
        tolerance="1e-10"
    />
    
    <size nstack="5000"/>
    
    <default>
        <joint limited="true" damping="0.1" armature="0.01"/>
        <motor ctrllimited="true" ctrlrange="-33.5 33.5"/>
        <geom contype="1" conaffinity="1" friction="1.0 0.1 0.1" rgba="0.5 0.6 0.7 1"/>
    </default>

    <worldbody>
        <light diffuse=".5 .5 .5" pos="0 0 3" dir="0 0 -1"/>
        <geom name="ground" type="plane" size="20 20 0.1" pos="0 0 0"/>
        
        <body name="trunk" pos="0 0 0.5">
            <joint type="free" limited="false"/>
            <geom type="box" size="0.2 0.1 0.05"/>
            
            <!-- Front right leg -->
            <body name="fr_hip" pos="0.18 -0.07 0">
                <joint name="fr_hip_joint" type="hinge" axis="0 0 1" range="-0.7 0.7"/>
                <geom type="cylinder" size="0.02 0.02" pos="0 0 0"/>
                
                <body name="fr_thigh" pos="0 -0.05 0">
                    <joint name="fr_thigh_joint" type="hinge" axis="1 0 0" range="-1.6 1.6"/>
                    <geom type="capsule" size="0.01" fromto="0 0 0 0 0 -0.12"/>
                    
                    <body name="fr_calf" pos="0 0 -0.12">
                        <joint name="fr_calf_joint" type="hinge" axis="1 0 0" range="-2.4 -0.4"/>
                        <geom type="capsule" size="0.008" fromto="0 0 0 0 0 -0.12"/>
                    </body>
                </body>
            </body>
        </body>
    </worldbody>
</mujoco> 